Workbook

Sheet Razon
A1: Razon de ausencua

Sheet Hoja 8
A3: 1. actualizar horarios del año | B3: https://docs.google.com/spreadsheets/d/1GjpRghQ7dRUq8-urxKF8BEGtZBh4hPqyd0mMf-jHQOY/edit#gid=344408511
A4: 2. actualizar fechas feirados

Sheet Inasistencias
B1: dia | C1: fecha | D1: hora | E1: Clase | F1: reemplaza | G1: Se pago Adicional? (sin permanencia) | H1: otro comentario | I1: Razon | J1: Ausente | K1: comentario | L1: Trajo Certificado? | M1: MES (AUTOMATICA)
B2: =C2 -> 45730 | C2: 45730 | E2: 5P | F2: Facundo Laborde | G2: # | I2: Sin profesor | J2: Maria del PIlar Fernandez | K2: NO ESTA REGISTRADO EN REMPLAZOS
B3: =C3 -> 45730 | C3: 45730 | E3: 5O | F3: Facundo Laborde | G3: # | I3: Sin profesor | J3: Maria del PIlar Fernandez | K3: NO ESTA REGISTRADO EN REMPLAZOS
B4: =C4 -> 45730 | C4: 45730 | E4: 5O | F4: Facundo Laborde | G4: # | I4: Sin profesor | J4: Maria del PIlar Fernandez | K4: NO ESTA REGISTRADO EN REMPLAZOS
B5: =C5 -> 45730 | C5: 45730 | I5: Sin profesor | J5: Maria del PIlar Fernandez | K5: NO ESTA REGISTRADO EN REMPLAZOS
B6: =C6 -> 45730 | C6: 45730 | I6: Sin profesor | J6: Maria del PIlar Fernandez | K6: NO ESTA REGISTRADO EN REMPLAZOS
B7: =C7 -> 45730 | C7: 45730 | E7: 4A | F7: Facundo Terrana | G7: # | I7: Sin profesor | J7: Maria del PIlar Fernandez | K7: NO ESTA REGISTRADO EN REMPLAZOS
B8: =C8 -> 45730 | C8: 45730 | E8: 4B | F8: Facundo Laborde | G8: # | I8: Sin profesor | J8: Maria del PIlar Fernandez | K8: NO ESTA REGISTRADO EN REMPLAZOS
B9: =C9 -> 45730 | C9: 45730 | E9: 4A | F9: Facundo Terrana | G9: # | I9: Sin profesor | J9: Maria del PIlar Fernandez | K9: NO ESTA REGISTRADO EN REMPLAZOS
B10: =C10 -> 45730 | C10: 45730 | D10: 2 | I10: Sin profesor | J10: Maria del PIlar Fernandez | K10: NO ESTA REGISTRADO EN REMPLAZOS
B11: =C11 -> 45730 | C11: 45730 | D11: 3 | E11: 5O | F11: Facundo Terrana | G11: # | I11: Sin profesor | J11: Maria del PIlar Fernandez | K11: NO ESTA REGISTRADO EN REMPLAZOS
B12: =C12 -> 45730 | C12: 45730 | D12: 4 | E12: 4B | F12: Facundo Terrana | G12: # | I12: Sin profesor | J12: Maria del PIlar Fernandez | K12: NO ESTA REGISTRADO EN REMPLAZOS
B13: =C13 -> 45730 | C13: 45730 | D13: 5 | E13: 5P | F13: Facundo Terrana | G13: # | I13: Sin profesor | J13: Maria del PIlar Fernandez | K13: NO ESTA REGISTRADO EN REMPLAZOS
B14: =C14 -> 45730 | C14: 45730 | D14: 6 | E14: 4B | F14: Facundo Terrana | G14: # | I14: Sin profesor | J14: Maria del PIlar Fernandez | K14: NO ESTA REGISTRADO EN REMPLAZOS
B15: =C15 -> 45733 | C15: 45733 | D15: 3 | E15: 2B | F15: Mercedes Vitullo | I15: Enfermedad | J15: Maria Soledad Arrambide | P15: https://oakhill.handing.co/posts/1062846
B16: =C16 -> 45733 | C16: 45733 | D16: 4 | I16: Enfermedad | J16: Maria Soledad Arrambide
B17: =C17 -> 45733 | C17: 45733 | D17: 5 | I17: Enfermedad | J17: Maria Soledad Arrambide
B18: =C18 -> 45733 | C18: 45733 | D18: 6 | I18: Enfermedad | J18: Maria Soledad Arrambide
B19: =C19 -> 45733 | C19: 45733 | D19: 7 | E19: 2A | F19: Astrid Vanina Santa Maria | I19: Enfermedad | J19: Maria Soledad Arrambide
B20: =C20 -> 45733 | C20: 45733 | D20: 8 | E20: 2A | F20: Carolina Ferrari Aldaz | G20: # | I20: Enfermedad | J20: Maria Soledad Arrambide
B21: =C21 -> 45733 | C21: 45733 | D21: 1 | E21: 6P | F21: Lucas Gerk | I21: Sin profesor
B22: =C22 -> 45733 | C22: 45733 | D22: 2 | E22: 6O | F22: Alvarez | I22: Sin profesor
B23: =C23 -> 45733 | C23: 45733 | D23: 3 | E23: 5P | F23: Alvarez | I23: Sin profesor
B24: =C24 -> 45733 | C24: 45733 | D24: 4 | E24: 5O | F24: Alvarez | I24: Sin profesor
B25: =C25 -> 45733 | C25: 45733 | D25: 4 | E25: 1A | F25: Aylén Junquet | I25: Capacitacion | J25: Maria Soledad Arrambide
B26: =C26 -> 45734 | C26: 45734 | D26: 1 | E26: 6 Basico | F26: Maria Guadalupe Reyes | I26: Preocupacional | J26: Silvana Morel
B27: =C27 -> 45734 | C27: 45734 | D27: 2 | E27: 6 Basico | F27: Maria Guadalupe Reyes | I27: Preocupacional | J27: Silvana Morel
B28: =C28 -> 45736 | C28: 45736 | D28: 1 | E28: 5P | F28: Facundo Laborde | G28: # | I28: Sin profesor | J28: Maria del PIlar Fernandez
B29: =C29 -> 45736 | C29: 45736 | D29: 2 | E29: 5O | F29: Facundo Laborde | G29: # | I29: Sin profesor | J29: Maria del PIlar Fernandez
B30: =C30 -> 45736 | C30: 45736 | D30: 3 | E30: 5O | F30: Facundo Laborde | G30: # | I30: Sin profesor | J30: Maria del PIlar Fernandez
B31: =C31 -> 45736 | C31: 45736 | D31: 4 | I31: Sin profesor | J31: Maria del PIlar Fernandez
B32: =C32 -> 45736 | C32: 45736 | D32: 5 | E32: 4A | F32: Facundo Terrana | G32: # | I32: Sin profesor | J32: Maria del PIlar Fernandez
B33: =C33 -> 45736 | C33: 45736 | D33: 6 | E33: 4B | F33: Facundo Laborde | G33: # | I33: Sin profesor | J33: Maria del PIlar Fernandez
B34: =C34 -> 45737 | C34: 45737 | D34: 6 | E34: 1A | H34: torneo | J34: Bentes
B35: =C35 -> 45737 | C35: 45737 | D35: 7 | E35: 1B | H35: torneo | J35: Bentes
B36: =C36 -> 45737 | C36: 45737 | D36: 8 | E36: 2B | F36: Bárbara Cornejo | G36: # | J36: Bentes
B37: =C37 -> 45737 | C37: 45737 | D37: 1 | E37: 6P | F37: Lucas Gerk | J37: Juan Bautista De Las Carreras
B38: =C38 -> 45737 | C38: 45737 | D38: 1 | E38: 3b | F38: Ezequiel Beccar Varela | G38: # | J38: Manuela Freire
B39: =C39 -> 45737 | C39: 45737 | D39: 2 | E39: 1B | J39: Manuela Freire
B40: =C40 -> 45737 | C40: 45737 | D40: 3 | E40: 2B | F40: Ezequiel Beccar Varela | G40: # | J40: Manuela Freire
...

Sheet Tabla dinámica 7

Sheet Tabla dinámica 3

Sheet AUSENCIA
C1: CANT de horas de clase del prof desde inicio de clases | D1: % ausencia de total de horas | F1: Nombre de chequeo
C2: =VLOOKUP(A2,'horas x profesor'!$A$5:$E$59,5,0) -> #N/A | D2: =G2 -> #N/A | F2: =VLOOKUP(A2,'horas x profesor'!$A$5:$E$59,1,0) -> #N/A | G2: =B2/C2*100 -> #N/A
C3: =VLOOKUP(A3,'horas x profesor'!$A$5:$E$59,5,0) -> 621.6 | D3: =G3 -> 0.64350064 | F3: =VLOOKUP(A3,'horas x profesor'!$A$5:$E$59,1,0) -> Agustina Bieule | G3: =B3/C3*100 -> 0.64350064
C4: =VLOOKUP(A4,'horas x profesor'!$A$5:$E$59,5,0) -> 532.8 | D4: =G4 -> 2.0645646 | F4: =VLOOKUP(A4,'horas x profesor'!$A$5:$E$59,1,0) -> Anechina | G4: =B4/C4*100 -> 2.0645646
C5: =VLOOKUP(A5,'horas x profesor'!$A$5:$E$59,5,0) -> 1716.8 | D5: =G5 -> 3.0871389 | F5: =VLOOKUP(A5,'horas x profesor'!$A$5:$E$59,1,0) -> Astrid Vanina Santa Maria | G5: =B5/C5*100 -> 3.0871389
C6: =VLOOKUP(A6,'horas x profesor'!$A$5:$E$59,5,0) -> 621.6 | D6: =G6 -> 0.64350064 | F6: =VLOOKUP(A6,'horas x profesor'!$A$5:$E$59,1,0) -> Bentes | G6: =B6/C6*100 -> 0.64350064
C7: =VLOOKUP(A7,'horas x profesor'!$A$5:$E$59,5,0) -> 370 | D7: =G7 -> 6.2162162 | F7: =VLOOKUP(A7,'horas x profesor'!$A$5:$E$59,1,0) -> Catalina Novo | G7: =B7/C7*100 -> 6.2162162
C8: =VLOOKUP(A8,'horas x profesor'!$A$5:$E$59,5,0) -> 1124.8 | D8: =G8 -> 2.5782361 | F8: =VLOOKUP(A8,'horas x profesor'!$A$5:$E$59,1,0) -> Cecilia Lund Petersen | G8: =B8/C8*100 -> 2.5782361
C9: =VLOOKUP(A9,'horas x profesor'!$A$5:$E$59,5,0) -> 1184 | D9: =G9 -> 0.92905405 | F9: =VLOOKUP(A9,'horas x profesor'!$A$5:$E$59,1,0) -> Cecilia Moirano | G9: =B9/C9*100 -> 0.92905405
C10: =VLOOKUP(A10,'horas x profesor'!$A$5:$E$59,5,0) -> 414.4 | D10: =G10 -> 0.96525097 | F10: =VLOOKUP(A10,'horas x profesor'!$A$5:$E$59,1,0) -> Clara Gobbée | G10: =B10/C10*100 -> 0.96525097
C11: =VLOOKUP(A11,'horas x profesor'!$A$5:$E$59,5,0) -> 236.8 | D11: =G11 -> 3.3783784 | F11: =VLOOKUP(A11,'horas x profesor'!$A$5:$E$59,1,0) -> Ezequiel Beccar Varela | G11: =B11/C11*100 -> 3.3783784
C12: =VLOOKUP(A12,'horas x profesor'!$A$5:$E$59,5,0) -> 266.4 | D12: =G12 -> 1.5015015 | F12: =VLOOKUP(A12,'horas x profesor'!$A$5:$E$59,1,0) -> Facundo Laborde | G12: =B12/C12*100 -> 1.5015015
C13: =VLOOKUP(A13,'horas x profesor'!$A$5:$E$59,5,0) -> 1302.4 | D13: =G13 -> 3.3783784 | F13: =VLOOKUP(A13,'horas x profesor'!$A$5:$E$59,1,0) -> Facundo Terrana | G13: =B13/C13*100 -> 3.3783784
... C40: =VLOOKUP(A40,'horas x profesor'!$A$5:$E$59,5,0) -> #N/A | D40: =G40 -> #N/A | F40: =VLOOKUP(A40,'horas x profesor'!$A$5:$E$59,1,0) -> #N/A | G40: =B40/C40*100 -> #N/A
C41: =VLOOKUP(A41,'horas x profesor'!$A$5:$E$59,5,0) -> #N/A | D41: =G41 | F41: =VLOOKUP(A41,'horas x profesor'!$A$5:$E$59,1,0) -> #N/A
C42: =VLOOKUP(A42,'horas x profesor'!$A$5:$E$59,5,0) -> #N/A | D42: =G42 | F42: =VLOOKUP(A42,'horas x profesor'!$A$5:$E$59,1,0) -> #N/A

Sheet horas x profesor
B1: 45721 | C1: =TODAY() -> 46134 | D1: ='Datos PUNTUALES'!C2 -> 296 | E1: ='Datos PUNTUALES'!D2 -> 59.2
B2: Inicio de clases | C2: HOY | D2: Dias | E2: semanas
E4: CANT de horas desde inicio de clases
A5: Marina Aberg Cobo | B5: 13 | E5: =$E$1*B5 -> 769.6 | J5: Marina Aberg Cobo | L5: 13
A6: Gabriel Aluzzo | B6: 19 | E6: =$E$1*B6 -> 1124.8 | J6: Gabriel Aluzzo | L6: 19
A7: Anechina | B7: 9 | E7: =$E$1*B7 -> 532.8 | J7: MARÍA EUGENIA ANECHINA | L7: 9
A8: Juan Ignacio Cacciamano | B8: 45 | E8: =$E$1*B8 -> 2664 | J8: #VALUE!
A9: Maria Soledad Arrambide | B9: 45 | E9: =$E$1*B9 -> 2664 | J9: Maria Soledad Arrambide | L9: 45
A10: Ezequiel Beccar Varela | B10: 4 | E10: =$E$1*B10 -> 236.8 | J10: BECCAR VARELA | K10: EZEQUIEL | L10: 4
A11: Bentes | B11: 10.5 | E11: =$E$1*B11 -> 621.6 | J11: BENTES | K11: Christiane | L11: 10.5
A12: Marcos Berro García | B12: 8.25 | E12: =$E$1*B12 -> 488.4 | J12: BERRO | K12: MARCOS | L12: 8.25
A13: Agustina Bieule | B13: 10.5 | E13: =$E$1*B13 -> 621.6 | J13: BIEULE Agustina | L13: 10.5
A14: María Guadalupe Blasco | B14: 16.25 | E14: =$E$1*B14 -> 962 | J14: BLASCO | K14: Guadalupe | L14: 16.25
A15: Verónica María Bonadeo | B15: 17 | E15: =$E$1*B15 -> 1006.4 | J15: BONADEO VERÓNICA | L15: 17
A16: Luciana Natalia Cabrera | B16: 19 | E16: =$E$1*B16 -> 1124.8 | J16: CABRERA | K16: Luciana | L16: 19
A17: CARLINO, Micaela | B17: 18 | E17: =$E$1*B17 -> 1065.6 | J17: CARLINO | K17: Micaela | L17: 18
A18: Valeria Denise Carmona | B18: 6.5 | E18: =$E$1*B18 -> 384.8 | J18: CARMONA | K18: Valeria | L18: 6.5
A19: Valeria Cerruti | B19: 16 | E19: =$E$1*B19 -> 947.2 | J19: CERUTTI | K19: VALERIA | L19: 16
A20: Bárbara Cornejo | B20: 6 | E20: =$E$1*B20 -> 355.2 | J20: CORNEJO | K20: Bárbara | L20: 6
A21: Juan Bautista De Las Carreras | B21: 45 | E21: =$E$1*B21 -> 2664 | J21: DE LAS CARRERAS Juan Bautista | L21: 45
A22: Cecilia Inés Dubini | B22: 8 | E22: =$E$1*B22 -> 473.6 | J22: DUBINI | K22: CECILIA | L22: 8
A23: Maria del PIlar Fernandez | B23: 13 | E23: =$E$1*B23 -> 769.6 | J23: FERNÁNDEZ | K23: PILAR | L23: 13
A24: Carolina Ferrari Aldaz | B24: 7 | E24: =$E$1*B24 -> 414.4 | J24: FERRARI ALDAZ CAROLINA | L24: 7
A25: Manuela Freire | B25: 7 | E25: =$E$1*B25 -> 414.4 | J25: FREIRE | K25: MANUELA | L25: 7
A26: Marcos Galván | B26: 8.38 | E26: =$E$1*B26 -> 496.096 | J26: GALVAN MARCOS | L26: 8.38
A27: Cecilia Garcia Reinoso | B27: 8 | E27: =$E$1*B27 -> 473.6 | J27: GARCIA REINOSO CECILIA | L27: 8
A28: Lucas Gerk | B28: 45 | E28: =$E$1*B28 -> 2664 | J28: Lucas Gerk | L28: 45
A29: Clara Gobbée | B29: 7 | E29: =$E$1*B29 -> 414.4 | J29: Clara Gobbée | L29: 7
A30: GONZALEZ MONDEJAR MARIANA | B30: 23 | E30: =$E$1*B30 -> 1361.6 | J30: GONZALEZ MONDEJAR MARIANA | L30: 23
A31: Martín Guareschi | B31: 4.38 | E31: =$E$1*B31 -> 259.296 | J31: GUARESCHI | K31: MARTÍN | L31: 4.38
A32: JUNQUET, AYLÉN | B32: 45 | E32: =$E$1*B32 -> 2664 | J32: JUNQUET | K32: AYLÉN | L32: 45
A33: Facundo Laborde | B33: 4.5 | E33: =$E$1*B33 -> 266.4 | J33: LABORDE | K33: Facundo | L33: 4.5
A34: Lucila Lago | B34: 18 | E34: =$E$1*B34 -> 1065.6 | J34: Lucila Lago | L34: 18
A35: María Laura Loyola | B35: 20 | E35: =$E$1*B35 -> 1184 | J35: LOYOLA MARIA LAURA | L35: 0
A36: Roberta Ludueña | B36: 27 | E36: =$E$1*B36 -> 1598.4 | J36: LUDUEÑA Roberta | L36: 27
A37: Cecilia Lund Petersen | B37: 19 | E37: =$E$1*B37 -> 1124.8 | J37: LUND PETERSEN CECILIA | L37: 19
A38: MAI NICOLAS | B38: 15 | E38: =$E$1*B38 -> 888 | J38: MAI NICOLAS | L38: 15
A39: MATHEU, Gonzalo | B39: 36 | E39: =$E$1*B39 -> 2131.2 | J39: MATHEU | K39: Gonzalo | L39: 36
A40: Diego Millet | B40: 8.38 | E40: =$E$1*B40 -> 496.096 | J40: MILLET DIEGO ANDRES | L40: 8.38
A41: Cecilia Moirano | B41: 20 | E41: =$E$1*B41 -> 1184 | J41: MOIRANO CECILIA | L41: 20
...

Sheet Profxdpto
A1: #REF! | E1: #REF!

Sheet Horas x dpto
A1: #REF! | C1: sin numeral | H1: #REF!
J3: =I3/$I$9 -> #DIV/0! | N3: =40*13 -> 520 | P3: =I10-N3 -> -520
J4: =I4/$I$9 -> #DIV/0! | P4: sobran
J5: =I5/$I$9 -> #DIV/0!
J6: =I6/$I$9 -> #DIV/0!
J7: =I7/$I$9 -> #DIV/0!
J8: =I8/$I$9 -> #DIV/0!

Sheet Datos PUNTUALES
A1: Inicio de clases | B1: HOY | C1: Dias | D1: Semanas de clases | E1: Hora de clases totales | F1: Ausencias | G1: % de ausencias | H1: =40*(3+2*5) -> 520 | I1: horas totalesx semana 2022 | O1: ABERG COBO | P1: Marina | R1: Staff | S1: ES | V1: Docentes | W1: mabergcobo@oakhillpilar.edu.ar | AC1: ABERG COBO, Marina
A2: 45721 | B2: =TODAY() -> 46134 | C2: =B4 -> 296 | D2: =C2/5 -> 59.2 | E2: =D2*H1 -> 30784 | F2: =SUM(AUSENCIA!B2:B200) -> 369 | G2: =F2/E2 -> 0.011986746 | O2: ALUZZO | P2: Gabriel | R2: Staff | S2: ES | V2: Docentes | W2: galuzzo@oakhillpilar.edu.ar | AC2: ALUZZO, Gabriel
O3: AQUINO | P3: Nelson | R3: Staff | S3: ES | V3: Admin.lectura | W3: naquino@oakhillpilar.edu.ar | AC3: AQUINO, Nelson
A4: NETWORKDAYS.INTL | B4: =_xlfn.NETWORKDAYS.INTL(A2,B2,1,H5:H43) -> 296 | O4: ARRAMBIDE | P4: Maria Soledad | R4: Staff | S4: ES | V4: Admin | W4: sarrambide@oakhillpilar.edu.ar | X4: solearrambide@gmail.com | Y4: 23967976 | Z4: 27181 | AC4: ARRAMBIDE, Maria Soledad
O5: AZQUETA | P5: Pilar | R5: Staff | S5: ES | V5: Admin.lectura | W5: pazqueta@oakhillpilar.edu.ar | X5: azquetapilar@gmail.com | Y5: 41472663 | Z5: 36034 | AC5: AZQUETA, Pilar
O6: BAECK | P6: Pablo | R6: Staff | S6: ES | V6: Docentes | W6: pbaeck@oakhillpilar.edu.ar | AC6: BAECK, Pablo
O7: BENTES | P7: Christiane | R7: Staff | S7: ES | V7: Docentes | W7: cbentes@oakhillpilar.edu.ar | X7: Cbentes035@gmail.com | Y7: 93620491 | Z7: 25092 | AC7: BENTES, Christiane
A8: PROFESORES | C8: RAZON | G8: FERIADOS | H8: 45379 | I8: 14. Jueves Santo | O8: BERRO GARCÍA | P8: Marcos | R8: Staff | S8: ES | V8: Docentes | W8: mberro@oakhillpilar.edu.ar | X8: marcosberro96@gmail.com | Y8: 39921499 | Z8: 35376 | AC8: BERRO GARCÍA, Marcos
A9: anika | C9: Enfermedad | H9: =H8+1 -> 45380 | I9: 15. Viernes Santo | O9: BIEULE | P9: Agustina | R9: Staff | S9: ES | V9: Docentes | W9: abieule@oakhillpilar.edu.ar | AC9: BIEULE, Agustina
A10: Agustina Bieule | C10: Familiar a cargo | H10: 45383 | I10: . Feriado con fines turísticos | O10: BLASCO | P10: María Guadalupe | R10: Staff | S10: EP / ES | U10: Docentes | V10: Docentes | W10: gblasco@oakhillpilar.edu.ar | X10: mgblasco95@gmail.com | Y10: 39000671 | Z10: 35027 | AC10: BLASCO, María Guadalupe
A11: Andrea Paez | C11: Aislamiento | H11: 45384 | I11: 2. Día del Veterano y de los Caídos en la Guerra de Malvinas | O11: BLAZQUEZ PARODI | P11: Camila Belen | R11: Staff | S11: ES | V11: Docentes | W11: cblazquez@oakhillpilar.edu.ar | X11: Camiblqz@gmail.com | Y11: 43573472 | Z11: 37224 | AC11: BLAZQUEZ PARODI, Camila Belen
A12: Anechina | C12: Licencia | H12: 45413 | I12: 2. Día del Veterano y de los Caídos en la Guerra de Malvina | O12: CABRERA | P12: Luciana Natalia | R12: Staff | S12: ES | V12: Docentes | W12: lcabrera@oakhillpilar.edu.ar | X12: cabreraluciananatalia@outlook.com | Y12: 38271145 | Z12: 34500 | AC12: CABRERA, Luciana Natalia
A13: Astrid Vanina Santa Maria | C13: Viaje Escolar | O13: CARLINO | P13: Micaela | R13: Staff | S13: ES | V13: Admin.lectura | W13: mcarlino@oakhillpilar.edu.ar | AC13: CARLINO, Micaela
A14: Aylén Junquet | C14: Turno/ Estudios Médicos | O14: CARMONA | P14: Valeria Denise | R14: Staff | S14: ES | V14: Docentes | W14: vcarmona@oakhillpilar.edu.ar | X14: valeriadenisecarmona@gmail.com | Y14: 38130066 | Z14: 34362 | AC14: CARMONA, Valeria Denise
A15: Bárbara Cornejo | C15: Problema Familiar | H15: 45463 | O15: CARUSO PRAHL | P15: Silvina | R15: Staff | S15: ES | V15: Admin | W15: scaruso@oakhillpilar.edu.ar | X15: silcarusoprahl@gmail.com | Y15: 23644015 | Z15: 26980 | AC15: CARUSO PRAHL, Silvina
A16: Bentes | C16: Licencia académica (Facultad) | H16: 45464 | O16: CORNEJO | P16: Bárbara | R16: Staff | S16: ES | V16: Docentes | W16: bcornejo@oakhillpilar.edu.ar | AC16: CORNEJO, Bárbara
A17: Carolina Ferrari Aldaz | C17: Trámite | H17: 45488 | I17: RECESO | O17: D'ADAMO | P17: María Martha | R17: Staff | S17: ES | V17: Docentes | W17: mdadamo@oakhillpilar.edu.ar | X17: marybonus2@gmail.com | Y17: 21055137 | Z17: 25407 | AC17: D'ADAMO, María Martha
A18: Catalina Novo | C18: Renuncia | H18: =H17+1 -> 45489 | I18: RECESO | O18: DE LAS CARRERAS | P18: Juan Bautista | R18: Staff | S18: ES | V18: Docentes | W18: bdelascarreras@oakhillpilar.edu.ar | AC18: DE LAS CARRERAS, Juan Bautista
A19: Cecilia Garcia Reinoso | C19: Reunión con padres | H19: =H18+1 -> 45490 | I19: RECESO | O19: DI FABIO | P19: Augusto | R19: Staff | S19: ES | V19: Docentes | W19: adifabio@oakhillpilar.edu.ar | AC19: DI FABIO, Augusto
A20: Cecilia Inés Dubini | C20: Tema Personal | H20: =H19+1 -> 45491 | I20: RECESO | O20: DUBINI | P20: Cecilia Inés | R20: Staff | S20: EP / ES | U20: Admin | V20: Docentes | W20: cdubini@oakhillpilar.edu.ar | X20: checha273@yahoo.com.ar | Y20: 22706578 | Z20: 26385 | AC20: DUBINI, Cecilia Inés
A21: Cecilia Lund Petersen | C21: Capacitacion | H21: =H20+1 -> 45492 | I21: RECESO | O21: FERRARI ALDAZ | P21: Carolina | R21: Staff | S21: ES | V21: Docentes | W21: cferrari@oakhillpilar.edu.ar | X21: caroferrari17@gmail.com | Y21: 23513827 | Z21: 27024 | AC21: FERRARI ALDAZ, Carolina
A22: Cecilia Moirano | C22: VIaje Personal | H22: =H21+1 -> 45493 | I22: RECESO | O22: FERRINO | P22: Sabrina Adriana | R22: Staff | S22: ES | V22: Docentes | W22: sferrino@oakhillpilar.edu.ar | AC22: FERRINO, Sabrina Adriana
A23: Clara Gobbée | C23: Evento Interno | H23: =H22+1 -> 45494 | I23: RECESO | O23: GALVÁN | P23: Marcos | R23: Staff | S23: ES | V23: Docentes | W23: mgalvan@oakhillpilar.edu.ar | X23: marcgalvan@hotmail.com | Y23: 22211266 | Z23: 26188 | AC23: GALVÁN, Marcos
A24: Diego Millet | C24: DEBATE | H24: =H23+1 -> 45495 | I24: RECESO | O24: GARCIA KOCH | P24: Cecilia | R24: Staff | S24: EP / ES | U24: Admin | V24: Fichas | W24: cgarciakoch@oakhillpilar.edu.ar | X24: ceciliagarciakoch@gmail.com | Y24: 24061700 | Z24: 27173 | AC24: GARCIA KOCH, Cecilia
A25: Eduardo Gabriel Rougier | H25: =H24+1 -> 45496 | I25: RECESO | O25: GARCIA REINOSO | P25: Cecilia | R25: Staff | S25: ES | V25: Docentes | W25: cgarciareinoso@oakhillpilar.edu.ar | X25: Ceciliagarciareinoso@gmail.com | Y25: 24068771 | Z25: 27221 | AC25: GARCIA REINOSO, Cecilia
A26: Ezequiel Beccar Varela | H26: =H25+1 -> 45497 | I26: RECESO | O26: GERK | P26: Lucas | R26: Staff | S26: ES | V26: Admin.lectura | W26: lgerk@oakhillpilar.edu.ar | AC26: GERK, Lucas
A27: Facundo Laborde | H27: =H26+1 -> 45498 | I27: RECESO | O27: GOBBÉE | P27: Clara | R27: Staff | S27: ES | V27: Docentes | W27: cgobbee@oakhillpilar.edu.ar | AC27: GOBBÉE, Clara
A28: Facundo Terrana | H28: =H27+1 -> 45499 | I28: RECESO | O28: GONZALEZ MONDEJAR | P28: Mariana Isabel | R28: Staff | S28: ES | V28: Admin | W28: mgonzalezmondejar@oakhillpilar.edu.ar | X28: mgmondejar@hotmail.com | Y28: 18171624 | Z28: 24615 | AC28: GONZALEZ MONDEJAR, Mariana Isabel
A29: Florencia Piolanti | H29: 45551 | I29: semana septiembre | O29: IBARRA | P29: Carla Rocio | R29: Staff | S29: ES | V29: Docentes | W29: cibarra@oakhillpilar.edu.ar | X29: carlarocioibarra@gmail.com | Y29: 35985350 | Z29: 33296 | AC29: IBARRA, Carla Rocio
A30: Gabriel Aluzzo | H30: =H29+1 -> 45552 | I30: semana septiembre | O30: IZE | P30: María Victoria | R30: Staff | S30: ES | V30: Docentes | W30: vize@oakhillpilar.edu.ar | X30: Victoriaize@yahoo.com | Y30: 24463214 | Z30: 27466 | AC30: IZE, María Victoria
A31: Helena Pérez Mendoza | H31: =H30+1 -> 45553 | I31: semana septiembre | O31: KIMMEL | P31: Norma Beatriz | R31: Staff | S31: ES | V31: Docentes | W31: nkimmel@oakhillpilar.edu.ar | X31: normakimmel2228@gmail.com | Y31: 13470647 | Z31: 21014 | AC31: KIMMEL, Norma Beatriz
A32: Iván Mauro Pasini | H32: =H31+1 -> 45554 | I32: semana septiembre | O32: LABORDE | P32: Facundo | R32: Staff | S32: ES | V32: Docentes | W32: flaborde@oakhillpilar.edu.ar | X32: labordefacu@gmail.com | Y32: 43974455 | Z32: 37273 | AC32: LABORDE, Facundo
A33: Juan Bautista De Las Carreras | O33: LOPEZ VILLAFAÑE | P33: María Victoria | R33: Staff | S33: ES | V33: Docentes | W33: mlopezvillafane@oakhillpilar.edu.ar | X33: lugarbsas@gmail.com | Y33: 21795284 | Z33: 25859 | AC33: LOPEZ VILLAFAÑE, María Victoria
A34: Juan Ignacio Cacciamano | H34: =H32+1 -> 45555 | I34: semana septiembre | O34: LOYOLA | P34: María Laura | R34: Staff | S34: ES | V34: Admin | W34: mloyola@oakhillpilar.edu.ar | X34: marucaloyola@hotmail.com | Y34: 17423961 | Z34: 20-07-64 | AC34: LOYOLA, María Laura
A35: Lucas Gerk | O35: LUDUEÑA | P35: Roberta | R35: Staff | S35: ES | V35: Docentes | W35: rluduena@oakhillpilar.edu.ar | AC35: LUDUEÑA, Roberta
A36: Luciana Natalia Cabrera | O36: LUND PETERSEN | P36: Cecilia | R36: Staff | S36: ES | V36: Docentes | W36: clundpetersen@oakhillpilar.edu.ar | X36: clundpetersen@yahoo.com.ar | Y36: 23157398 | Z36: 26632 | AC36: LUND PETERSEN, Cecilia
A37: Lucila Lago | O37: MAI | P37: Nicolás Leonel | R37: Staff | S37: EP / ES | U37: Docentes | V37: Docentes | W37: nmai@oakhillpilar.edu.ar | AC37: MAI, Nicolás Leonel
A38: Manuela Freire | O38: MARTIN MULLER | P38: Sofia Constanza | R38: Staff | S38: ES | V38: Docentes | W38: smartinmuller@oakhillpilar.edu.ar | X38: Sofiac.mmuller@gmail.com | Y38: 36215077 | Z38: 33392 | AC38: MARTIN MULLER, Sofia Constanza
A39: Marcos Berro García | O39: MATHEU | P39: Gonzalo Jose | R39: Staff | S39: ES | V39: Admin | W39: gmatheu@oakhillpilar.edu.ar | X39: gonzalomatheu@yahoo.com.ar | Y39: 25803236 | Z39: 28308 | AC39: MATHEU, Gonzalo Jose
A40: Marcos Galván | O40: MILLET | P40: Diego | R40: Staff | S40: EP / ES | U40: Docentes | V40: Docentes | W40: dmillet@oakhillpilar.edu.ar | AC40: MILLET, Diego
...

Sheet staf25
B1: =IFERROR(__xludf.DUMMYFUNCTION("importrange(""https://docs.google.com/spreadsheets/d/1l_1sOLfBURPAbokKUq0rIbKCqWIwmYZYZv9KpMl_kxc/edit?gid=2100274340#gid=2100274340"",""Docentes y Materias!b3:Q"")"),"Nº") -> Nº | C1: =IFERROR(__xludf.DUMMYFUNCTION("""COMPUTED_VALUE"""),"CURSO") -> CURSO | D1: =IFERROR(__xludf.DUMMYFUNCTION("""COMPUTED_VALUE"""),"ID GRUPO") -> ID GRUPO | E1: =IFERROR(__xludf.DUMMYFUNCTION("""COMPUTED_VALUE"""),"ID") -> ID | F1: =IFERROR(__xludf.DUMMYFUNCTION("""COMPUTED_VALUE"""),"AGRUPAR") -> AGRUPAR | G1: =IFERROR(__xludf.DUMMYFUNCTION("""COMPUTED_VALUE"""),"OFICIAL") -> OFICIAL | H1: =IFERROR(__xludf.DUMMYFUNCTION("""COMPUTED_VALUE"""),"ESCALA") -> ESCALA | I1: =IFERROR(__xludf.DUMMYFUNCTION("""COMPUTED_VALUE"""),"CARGA HORARIA") -> CARGA HORARIA | K1: =IFERROR(__xludf.DUMMYFUNCTION("""COMPUTED_VALUE"""),"MATERIA") -> MATERIA | L1: =IFERROR(__xludf.DUMMYFUNCTION("""COMPUTED_VALUE"""),"DOCENTE 2024") -> DOCENTE 2024 | M1: =IFERROR(__xludf.DUMMYFUNCTION("""COMPUTED_VALUE"""),"DOCENTE 2024") -> DOCENTE 2024 | O1: =IFERROR(__xludf.DUMMYFUNCTION("""COMPUTED_VALUE"""),"DOCENTE 2025") -> DOCENTE 2025 | P1: =IFERROR(__xludf.DUMMYFUNCTION("""COMPUTED_VALUE"""),"Departamento") -> Departamento | Q1: =IFERROR(__xludf.DUMMYFUNCTION("""COMPUTED_VALUE"""),"Razon de cambio") -> Razon de cambio
A2: =O2 -> Gabriel Aluzzo | B2: =IFERROR(__xludf.DUMMYFUNCTION("""COMPUTED_VALUE"""),1.0) -> 1 | C2: =IFERROR(__xludf.DUMMYFUNCTION("""COMPUTED_VALUE"""),"1º A") -> 1º A | G2: =IFERROR(__xludf.DUMMYFUNCTION("""COMPUTED_VALUE"""),"si") -> si | I2: =IFERROR(__xludf.DUMMYFUNCTION("""COMPUTED_VALUE"""),2.0) -> 2 | J2: =IFERROR(__xludf.DUMMYFUNCTION("""COMPUTED_VALUE""")," ES 2025") -> ES 2025 | K2: =IFERROR(__xludf.DUMMYFUNCTION("""COMPUTED_VALUE"""),"Arte") -> Arte | L2: =IFERROR(__xludf.DUMMYFUNCTION("""COMPUTED_VALUE"""),"Gabriel Aluzzo") -> Gabriel Aluzzo | O2: =IFERROR(__xludf.DUMMYFUNCTION("""COMPUTED_VALUE"""),"Gabriel Aluzzo") -> Gabriel Aluzzo | P2: =IFERROR(__xludf.DUMMYFUNCTION("""COMPUTED_VALUE"""),"Expresion") -> Expresion | Q2: =IFERROR(__xludf.DUMMYFUNCTION("""COMPUTED_VALUE"""),"Mantiene") -> Mantiene
A3: =O3 -> Gabriel Aluzzo | B3: =IFERROR(__xludf.DUMMYFUNCTION("""COMPUTED_VALUE"""),1.0) -> 1 | C3: =IFERROR(__xludf.DUMMYFUNCTION("""COMPUTED_VALUE"""),"1º B") -> 1º B | G3: =IFERROR(__xludf.DUMMYFUNCTION("""COMPUTED_VALUE"""),"si") -> si | I3: =IFERROR(__xludf.DUMMYFUNCTION("""COMPUTED_VALUE"""),2.0) -> 2 | K3: =IFERROR(__xludf.DUMMYFUNCTION("""COMPUTED_VALUE"""),"Arte") -> Arte | L3: =IFERROR(__xludf.DUMMYFUNCTION("""COMPUTED_VALUE"""),"Gabriel Aluzzo") -> Gabriel Aluzzo | O3: =IFERROR(__xludf.DUMMYFUNCTION("""COMPUTED_VALUE"""),"Gabriel Aluzzo") -> Gabriel Aluzzo | P3: =IFERROR(__xludf.DUMMYFUNCTION("""COMPUTED_VALUE"""),"Expresion") -> Expresion | Q3: =IFERROR(__xludf.DUMMYFUNCTION("""COMPUTED_VALUE"""),"Mantiene") -> Mantiene
A4: =O4 -> María Laura Loyola | B4: =IFERROR(__xludf.DUMMYFUNCTION("""COMPUTED_VALUE"""),2.0) -> 2 | C4: =IFERROR(__xludf.DUMMYFUNCTION("""COMPUTED_VALUE"""),"1º A") -> 1º A | G4: =IFERROR(__xludf.DUMMYFUNCTION("""COMPUTED_VALUE"""),"si") -> si | I4: =IFERROR(__xludf.DUMMYFUNCTION("""COMPUTED_VALUE"""),4.0) -> 4 | K4: =IFERROR(__xludf.DUMMYFUNCTION("""COMPUTED_VALUE"""),"Ciencias Sociales") -> Ciencias Sociales | L4: =IFERROR(__xludf.DUMMYFUNCTION("""COMPUTED_VALUE"""),"María Laura Loyola") -> María Laura Loyola | O4: =IFERROR(__xludf.DUMMYFUNCTION("""COMPUTED_VALUE"""),"María Laura Loyola") -> María Laura Loyola | P4: =IFERROR(__xludf.DUMMYFUNCTION("""COMPUTED_VALUE"""),"Humanas") -> Humanas | Q4: =IFERROR(__xludf.DUMMYFUNCTION("""COMPUTED_VALUE"""),"Mantiene") -> Mantiene
A5: =O5 -> María Laura Loyola | B5: =IFERROR(__xludf.DUMMYFUNCTION("""COMPUTED_VALUE"""),2.0) -> 2 | C5: =IFERROR(__xludf.DUMMYFUNCTION("""COMPUTED_VALUE"""),"1º B") -> 1º B | G5: =IFERROR(__xludf.DUMMYFUNCTION("""COMPUTED_VALUE"""),"si") -> si | I5: =IFERROR(__xludf.DUMMYFUNCTION("""COMPUTED_VALUE"""),4.0) -> 4 | K5: =IFERROR(__xludf.DUMMYFUNCTION("""COMPUTED_VALUE"""),"Ciencias Sociales") -> Ciencias Sociales | L5: =IFERROR(__xludf.DUMMYFUNCTION("""COMPUTED_VALUE"""),"María Laura Loyola") -> María Laura Loyola | O5: =IFERROR(__xludf.DUMMYFUNCTION("""COMPUTED_VALUE""")," María Laura Loyola ") -> María Laura Loyola | P5: =IFERROR(__xludf.DUMMYFUNCTION("""COMPUTED_VALUE"""),"Humanas") -> Humanas | Q5: =IFERROR(__xludf.DUMMYFUNCTION("""COMPUTED_VALUE"""),"Mantiene") -> Mantiene
A6: =O6 -> Maria Laura Muiño | B6: =IFERROR(__xludf.DUMMYFUNCTION("""COMPUTED_VALUE"""),3.0) -> 3 | C6: =IFERROR(__xludf.DUMMYFUNCTION("""COMPUTED_VALUE"""),"1º A") -> 1º A | G6: =IFERROR(__xludf.DUMMYFUNCTION("""COMPUTED_VALUE"""),"si") -> si | I6: =IFERROR(__xludf.DUMMYFUNCTION("""COMPUTED_VALUE"""),4.0) -> 4 | K6: =IFERROR(__xludf.DUMMYFUNCTION("""COMPUTED_VALUE"""),"Educación Física") -> Educación Física | L6: =IFERROR(__xludf.DUMMYFUNCTION("""COMPUTED_VALUE"""),"Laura Muiño") -> Laura Muiño | M6: =IFERROR(__xludf.DUMMYFUNCTION("""COMPUTED_VALUE"""),"Marcos Galván") -> Marcos Galván | O6: =IFERROR(__xludf.DUMMYFUNCTION("""COMPUTED_VALUE""")," Maria Laura Muiño ") -> Maria Laura Muiño | P6: =IFERROR(__xludf.DUMMYFUNCTION("""COMPUTED_VALUE"""),"Educación Física") -> Educación Física | Q6: =IFERROR(__xludf.DUMMYFUNCTION("""COMPUTED_VALUE"""),"CAMBIA HORAS?") -> CAMBIA HORAS?
A7: =O7 -> Diego Millet | B7: =IFERROR(__xludf.DUMMYFUNCTION("""COMPUTED_VALUE"""),3.0) -> 3 | C7: =IFERROR(__xludf.DUMMYFUNCTION("""COMPUTED_VALUE"""),"1º B") -> 1º B | G7: =IFERROR(__xludf.DUMMYFUNCTION("""COMPUTED_VALUE"""),"si") -> si | I7: =IFERROR(__xludf.DUMMYFUNCTION("""COMPUTED_VALUE"""),4.0) -> 4 | K7: =IFERROR(__xludf.DUMMYFUNCTION("""COMPUTED_VALUE"""),"Educación Física") -> Educación Física | L7: =IFERROR(__xludf.DUMMYFUNCTION("""COMPUTED_VALUE"""),"Diego Millet") -> Diego Millet | M7: =IFERROR(__xludf.DUMMYFUNCTION("""COMPUTED_VALUE"""),"Marcos Galván") -> Marcos Galván | O7: =IFERROR(__xludf.DUMMYFUNCTION("""COMPUTED_VALUE"""),"Diego Millet") -> Diego Millet | P7: =IFERROR(__xludf.DUMMYFUNCTION("""COMPUTED_VALUE"""),"Educación Física") -> Educación Física | Q7: =IFERROR(__xludf.DUMMYFUNCTION("""COMPUTED_VALUE"""),"CAMBIA HORAS?") -> CAMBIA HORAS?
A8: =O8 -> Maria Soledad Arrambide | B8: =IFERROR(__xludf.DUMMYFUNCTION("""COMPUTED_VALUE"""),4.0) -> 4 | C8: =IFERROR(__xludf.DUMMYFUNCTION("""COMPUTED_VALUE"""),"1º A") -> 1º A | G8: =IFERROR(__xludf.DUMMYFUNCTION("""COMPUTED_VALUE"""),"si") -> si | I8: =IFERROR(__xludf.DUMMYFUNCTION("""COMPUTED_VALUE"""),6.0) -> 6 | K8: =IFERROR(__xludf.DUMMYFUNCTION("""COMPUTED_VALUE"""),"English") -> English | L8: =IFERROR(__xludf.DUMMYFUNCTION("""COMPUTED_VALUE"""),"Maria Soledad Arrambide") -> Maria Soledad Arrambide | O8: =IFERROR(__xludf.DUMMYFUNCTION("""COMPUTED_VALUE"""),"Maria Soledad Arrambide") -> Maria Soledad Arrambide | P8: =IFERROR(__xludf.DUMMYFUNCTION("""COMPUTED_VALUE"""),"Expresion") -> Expresion | Q8: =IFERROR(__xludf.DUMMYFUNCTION("""COMPUTED_VALUE"""),"Mantiene") -> Mantiene
A9: =O9 -> Maria Soledad Arrambide | B9: =IFERROR(__xludf.DUMMYFUNCTION("""COMPUTED_VALUE"""),4.0) -> 4 | C9: =IFERROR(__xludf.DUMMYFUNCTION("""COMPUTED_VALUE"""),"1º B") -> 1º B | G9: =IFERROR(__xludf.DUMMYFUNCTION("""COMPUTED_VALUE"""),"si") -> si | I9: =IFERROR(__xludf.DUMMYFUNCTION("""COMPUTED_VALUE"""),6.0) -> 6 | K9: =IFERROR(__xludf.DUMMYFUNCTION("""COMPUTED_VALUE"""),"English") -> English | L9: =IFERROR(__xludf.DUMMYFUNCTION("""COMPUTED_VALUE"""),"Maria Soledad Arrambide") -> Maria Soledad Arrambide | O9: =IFERROR(__xludf.DUMMYFUNCTION("""COMPUTED_VALUE"""),"Maria Soledad Arrambide") -> Maria Soledad Arrambide | P9: =IFERROR(__xludf.DUMMYFUNCTION("""COMPUTED_VALUE"""),"Expresion") -> Expresion | Q9: =IFERROR(__xludf.DUMMYFUNCTION("""COMPUTED_VALUE"""),"Mantiene") -> Mantiene
A10: =O10 -> Verónica María Bonadeo | B10: =IFERROR(__xludf.DUMMYFUNCTION("""COMPUTED_VALUE"""),5.0) -> 5 | C10: =IFERROR(__xludf.DUMMYFUNCTION("""COMPUTED_VALUE"""),"1º A") -> 1º A | I10: =IFERROR(__xludf.DUMMYFUNCTION("""COMPUTED_VALUE"""),1.0) -> 1 | K10: =IFERROR(__xludf.DUMMYFUNCTION("""COMPUTED_VALUE"""),"Estudio Dirigido") -> Estudio Dirigido | L10: =IFERROR(__xludf.DUMMYFUNCTION("""COMPUTED_VALUE"""),"Verónica María Bonadeo") -> Verónica María Bonadeo | O10: =IFERROR(__xludf.DUMMYFUNCTION("""COMPUTED_VALUE"""),"Verónica María Bonadeo") -> Verónica María Bonadeo | P10: =IFERROR(__xludf.DUMMYFUNCTION("""COMPUTED_VALUE"""),"Orientacion") -> Orientacion | Q10: =IFERROR(__xludf.DUMMYFUNCTION("""COMPUTED_VALUE"""),"Mantiene") -> Mantiene
A11: =O11 -> Verónica María Bonadeo | B11: =IFERROR(__xludf.DUMMYFUNCTION("""COMPUTED_VALUE"""),5.0) -> 5 | C11: =IFERROR(__xludf.DUMMYFUNCTION("""COMPUTED_VALUE"""),"1º B") -> 1º B | I11: =IFERROR(__xludf.DUMMYFUNCTION("""COMPUTED_VALUE"""),1.0) -> 1 | K11: =IFERROR(__xludf.DUMMYFUNCTION("""COMPUTED_VALUE"""),"Estudio Dirigido") -> Estudio Dirigido | L11: =IFERROR(__xludf.DUMMYFUNCTION("""COMPUTED_VALUE"""),"Verónica María Bonadeo") -> Verónica María Bonadeo | O11: =IFERROR(__xludf.DUMMYFUNCTION("""COMPUTED_VALUE"""),"Verónica María Bonadeo") -> Verónica María Bonadeo | P11: =IFERROR(__xludf.DUMMYFUNCTION("""COMPUTED_VALUE"""),"Orientacion") -> Orientacion | Q11: =IFERROR(__xludf.DUMMYFUNCTION("""COMPUTED_VALUE"""),"Mantiene") -> Mantiene
A12: =O12 -> Agustina Bieule | B12: =IFERROR(__xludf.DUMMYFUNCTION("""COMPUTED_VALUE"""),6.0) -> 6 | C12: =IFERROR(__xludf.DUMMYFUNCTION("""COMPUTED_VALUE"""),"1º A") -> 1º A | I12: =IFERROR(__xludf.DUMMYFUNCTION("""COMPUTED_VALUE"""),2.0) -> 2 | K12: =IFERROR(__xludf.DUMMYFUNCTION("""COMPUTED_VALUE"""),"Formación Católica") -> Formación Católica | L12: =IFERROR(__xludf.DUMMYFUNCTION("""COMPUTED_VALUE"""),"Agustina Bieule") -> Agustina Bieule | O12: =IFERROR(__xludf.DUMMYFUNCTION("""COMPUTED_VALUE"""),"Agustina Bieule") -> Agustina Bieule | P12: =IFERROR(__xludf.DUMMYFUNCTION("""COMPUTED_VALUE"""),"Formación Católica") -> Formación Católica | Q12: =IFERROR(__xludf.DUMMYFUNCTION("""COMPUTED_VALUE"""),"Mantiene") -> Mantiene
A13: =O13 -> Helena Pérez Mendoza | B13: =IFERROR(__xludf.DUMMYFUNCTION("""COMPUTED_VALUE"""),6.0) -> 6 | C13: =IFERROR(__xludf.DUMMYFUNCTION("""COMPUTED_VALUE"""),"1º B") -> 1º B | I13: =IFERROR(__xludf.DUMMYFUNCTION("""COMPUTED_VALUE"""),2.0) -> 2 | K13: =IFERROR(__xludf.DUMMYFUNCTION("""COMPUTED_VALUE"""),"Formación Católica") -> Formación Católica | L13: =IFERROR(__xludf.DUMMYFUNCTION("""COMPUTED_VALUE"""),"Juan Ignacio Pietrodarca") -> Juan Ignacio Pietrodarca | O13: =IFERROR(__xludf.DUMMYFUNCTION("""COMPUTED_VALUE"""),"Helena Pérez Mendoza") -> Helena Pérez Mendoza | P13: =IFERROR(__xludf.DUMMYFUNCTION("""COMPUTED_VALUE"""),"Formación Católica") -> Formación Católica | Q13: =IFERROR(__xludf.DUMMYFUNCTION("""COMPUTED_VALUE"""),"Nuevo x baja de profesor") -> Nuevo x baja de profesor
A14: =O14 -> Verónica María Bonadeo | B14: =IFERROR(__xludf.DUMMYFUNCTION("""COMPUTED_VALUE"""),7.0) -> 7 | C14: =IFERROR(__xludf.DUMMYFUNCTION("""COMPUTED_VALUE"""),"1º A") -> 1º A | I14: =IFERROR(__xludf.DUMMYFUNCTION("""COMPUTED_VALUE"""),1.0) -> 1 | K14: =IFERROR(__xludf.DUMMYFUNCTION("""COMPUTED_VALUE"""),"Information Technology") -> Information Technology | L14: =IFERROR(__xludf.DUMMYFUNCTION("""COMPUTED_VALUE"""),"Verónica María Bonadeo") -> Verónica María Bonadeo | O14: =IFERROR(__xludf.DUMMYFUNCTION("""COMPUTED_VALUE""")," Verónica María Bonadeo ") -> Verónica María Bonadeo | P14: =IFERROR(__xludf.DUMMYFUNCTION("""COMPUTED_VALUE"""),"Tecnologia") -> Tecnologia | Q14: =IFERROR(__xludf.DUMMYFUNCTION("""COMPUTED_VALUE"""),"Mantiene") -> Mantiene
A15: =O15 -> Verónica María Bonadeo | B15: =IFERROR(__xludf.DUMMYFUNCTION("""COMPUTED_VALUE"""),7.0) -> 7 | C15: =IFERROR(__xludf.DUMMYFUNCTION("""COMPUTED_VALUE"""),"1º B") -> 1º B | I15: =IFERROR(__xludf.DUMMYFUNCTION("""COMPUTED_VALUE"""),1.0) -> 1 | K15: =IFERROR(__xludf.DUMMYFUNCTION("""COMPUTED_VALUE"""),"Information Technology") -> Information Technology | L15: =IFERROR(__xludf.DUMMYFUNCTION("""COMPUTED_VALUE"""),"Eduardo Gabriel Rougier") -> Eduardo Gabriel Rougier | M15: =IFERROR(__xludf.DUMMYFUNCTION("""COMPUTED_VALUE"""),"Verónica María Bonadeo") -> Verónica María Bonadeo | O15: =IFERROR(__xludf.DUMMYFUNCTION("""COMPUTED_VALUE""")," Verónica María Bonadeo ") -> Verónica María Bonadeo | P15: =IFERROR(__xludf.DUMMYFUNCTION("""COMPUTED_VALUE"""),"Tecnologia") -> Tecnologia | Q15: =IFERROR(__xludf.DUMMYFUNCTION("""COMPUTED_VALUE"""),"Nuevo") -> Nuevo
A16: =O16 -> Catalina Novo | B16: =IFERROR(__xludf.DUMMYFUNCTION("""COMPUTED_VALUE"""),8.0) -> 8 | C16: =IFERROR(__xludf.DUMMYFUNCTION("""COMPUTED_VALUE"""),"1º A") -> 1º A | G16: =IFERROR(__xludf.DUMMYFUNCTION("""COMPUTED_VALUE"""),"si") -> si | I16: =IFERROR(__xludf.DUMMYFUNCTION("""COMPUTED_VALUE"""),2.0) -> 2 | K16: =IFERROR(__xludf.DUMMYFUNCTION("""COMPUTED_VALUE"""),"Liderazgo al Servicio") -> Liderazgo al Servicio | L16: =IFERROR(__xludf.DUMMYFUNCTION("""COMPUTED_VALUE"""),"Carolina Ferrari Aldaz") -> Carolina Ferrari Aldaz | O16: =IFERROR(__xludf.DUMMYFUNCTION("""COMPUTED_VALUE""")," Catalina Novo ") -> Catalina Novo | P16: =IFERROR(__xludf.DUMMYFUNCTION("""COMPUTED_VALUE"""),"Formación Católica") -> Formación Católica | Q16: =IFERROR(__xludf.DUMMYFUNCTION("""COMPUTED_VALUE"""),"Nuevo x baja de profesor?????") -> Nuevo x baja de profesor?????
A17: =O17 -> Manuela Freire | B17: =IFERROR(__xludf.DUMMYFUNCTION("""COMPUTED_VALUE"""),8.0) -> 8 | C17: =IFERROR(__xludf.DUMMYFUNCTION("""COMPUTED_VALUE"""),"1º B") -> 1º B | G17: =IFERROR(__xludf.DUMMYFUNCTION("""COMPUTED_VALUE"""),"si") -> si | I17: =IFERROR(__xludf.DUMMYFUNCTION("""COMPUTED_VALUE"""),2.0) -> 2 | K17: =IFERROR(__xludf.DUMMYFUNCTION("""COMPUTED_VALUE"""),"Liderazgo al Servicio") -> Liderazgo al Servicio | L17: =IFERROR(__xludf.DUMMYFUNCTION("""COMPUTED_VALUE"""),"Carolina Ferrari Aldaz") -> Carolina Ferrari Aldaz | O17: =IFERROR(__xludf.DUMMYFUNCTION("""COMPUTED_VALUE""")," Manuela Freire ") -> Manuela Freire | P17: =IFERROR(__xludf.DUMMYFUNCTION("""COMPUTED_VALUE"""),"Formación Católica") -> Formación Católica | Q17: =IFERROR(__xludf.DUMMYFUNCTION("""COMPUTED_VALUE"""),"Nuevo x baja de profesor?????") -> Nuevo x baja de profesor?????
A18: =O18 -> Astrid Vanina Santa Maria | B18: =IFERROR(__xludf.DUMMYFUNCTION("""COMPUTED_VALUE"""),9.0) -> 9 | C18: =IFERROR(__xludf.DUMMYFUNCTION("""COMPUTED_VALUE"""),"1º A") -> 1º A | I18: =IFERROR(__xludf.DUMMYFUNCTION("""COMPUTED_VALUE"""),2.0) -> 2 | K18: =IFERROR(__xludf.DUMMYFUNCTION("""COMPUTED_VALUE"""),"Literature") -> Literature | L18: =IFERROR(__xludf.DUMMYFUNCTION("""COMPUTED_VALUE"""),"María Martha D'Adamo") -> María Martha D'Adamo | N18: =IFERROR(__xludf.DUMMYFUNCTION("""COMPUTED_VALUE"""),"María Martha D'Adamo") -> María Martha D'Adamo | O18: =IFERROR(__xludf.DUMMYFUNCTION("""COMPUTED_VALUE"""),"Astrid Vanina Santa Maria") -> Astrid Vanina Santa Maria | P18: =IFERROR(__xludf.DUMMYFUNCTION("""COMPUTED_VALUE"""),"Expresion") -> Expresion | Q18: =IFERROR(__xludf.DUMMYFUNCTION("""COMPUTED_VALUE"""),"Nuevo x baja de profesor") -> Nuevo x baja de profesor
A19: =O19 -> Astrid Vanina Santa Maria | B19: =IFERROR(__xludf.DUMMYFUNCTION("""COMPUTED_VALUE"""),9.0) -> 9 | C19: =IFERROR(__xludf.DUMMYFUNCTION("""COMPUTED_VALUE"""),"1º B") -> 1º B | I19: =IFERROR(__xludf.DUMMYFUNCTION("""COMPUTED_VALUE"""),2.0) -> 2 | K19: =IFERROR(__xludf.DUMMYFUNCTION("""COMPUTED_VALUE"""),"Literature") -> Literature | L19: =IFERROR(__xludf.DUMMYFUNCTION("""COMPUTED_VALUE"""),"María Victoria Ize") -> María Victoria Ize | O19: =IFERROR(__xludf.DUMMYFUNCTION("""COMPUTED_VALUE""")," Astrid Vanina Santa Maria ") -> Astrid Vanina Santa Maria | P19: =IFERROR(__xludf.DUMMYFUNCTION("""COMPUTED_VALUE"""),"Expresion") -> Expresion | Q19: =IFERROR(__xludf.DUMMYFUNCTION("""COMPUTED_VALUE"""),"Nuevo x baja de profesor") -> Nuevo x baja de profesor
A20: =O20 -> María Gabriela Redolfi | B20: =IFERROR(__xludf.DUMMYFUNCTION("""COMPUTED_VALUE"""),10.0) -> 10 | C20: =IFERROR(__xludf.DUMMYFUNCTION("""COMPUTED_VALUE"""),"1º A") -> 1º A | G20: =IFERROR(__xludf.DUMMYFUNCTION("""COMPUTED_VALUE"""),"si") -> si | I20: =IFERROR(__xludf.DUMMYFUNCTION("""COMPUTED_VALUE"""),4.0) -> 4 | K20: =IFERROR(__xludf.DUMMYFUNCTION("""COMPUTED_VALUE"""),"Maths") -> Maths | L20: =IFERROR(__xludf.DUMMYFUNCTION("""COMPUTED_VALUE"""),"María Gabriela Redolfi") -> María Gabriela Redolfi | O20: =IFERROR(__xludf.DUMMYFUNCTION("""COMPUTED_VALUE"""),"María Gabriela Redolfi") -> María Gabriela Redolfi | P20: =IFERROR(__xludf.DUMMYFUNCTION("""COMPUTED_VALUE"""),"Exactas") -> Exactas | Q20: =IFERROR(__xludf.DUMMYFUNCTION("""COMPUTED_VALUE"""),"Mantiene") -> Mantiene
A21: =O21 -> María Gabriela Redolfi | B21: =IFERROR(__xludf.DUMMYFUNCTION("""COMPUTED_VALUE"""),10.0) -> 10 | C21: =IFERROR(__xludf.DUMMYFUNCTION("""COMPUTED_VALUE"""),"1º B") -> 1º B | G21: =IFERROR(__xludf.DUMMYFUNCTION("""COMPUTED_VALUE"""),"si") -> si | I21: =IFERROR(__xludf.DUMMYFUNCTION("""COMPUTED_VALUE"""),4.0) -> 4 | K21: =IFERROR(__xludf.DUMMYFUNCTION("""COMPUTED_VALUE"""),"Maths") -> Maths | L21: =IFERROR(__xludf.DUMMYFUNCTION("""COMPUTED_VALUE"""),"María Gabriela Redolfi") -> María Gabriela Redolfi | O21: =IFERROR(__xludf.DUMMYFUNCTION("""COMPUTED_VALUE""")," María Gabriela Redolfi ") -> María Gabriela Redolfi | P21: =IFERROR(__xludf.DUMMYFUNCTION("""COMPUTED_VALUE"""),"Exactas") -> Exactas | Q21: =IFERROR(__xludf.DUMMYFUNCTION("""COMPUTED_VALUE"""),"Mantiene") -> Mantiene
A22: =O22 -> Facundo Laborde | B22: =IFERROR(__xludf.DUMMYFUNCTION("""COMPUTED_VALUE"""),11.0) -> 11 | C22: =IFERROR(__xludf.DUMMYFUNCTION("""COMPUTED_VALUE"""),"1º A") -> 1º A | I22: =IFERROR(__xludf.DUMMYFUNCTION("""COMPUTED_VALUE"""),1.0) -> 1 | K22: =IFERROR(__xludf.DUMMYFUNCTION("""COMPUTED_VALUE"""),"Música") -> Música | L22: =IFERROR(__xludf.DUMMYFUNCTION("""COMPUTED_VALUE"""),"Facundo Laborde") -> Facundo Laborde | O22: =IFERROR(__xludf.DUMMYFUNCTION("""COMPUTED_VALUE""")," Facundo Laborde ") -> Facundo Laborde | P22: =IFERROR(__xludf.DUMMYFUNCTION("""COMPUTED_VALUE"""),"Expresion") -> Expresion | Q22: =IFERROR(__xludf.DUMMYFUNCTION("""COMPUTED_VALUE"""),"Mantiene") -> Mantiene
A23: =O23 -> Facundo Laborde | B23: =IFERROR(__xludf.DUMMYFUNCTION("""COMPUTED_VALUE"""),11.0) -> 11 | C23: =IFERROR(__xludf.DUMMYFUNCTION("""COMPUTED_VALUE"""),"1º B") -> 1º B | I23: =IFERROR(__xludf.DUMMYFUNCTION("""COMPUTED_VALUE"""),1.0) -> 1 | K23: =IFERROR(__xludf.DUMMYFUNCTION("""COMPUTED_VALUE"""),"Música") -> Música | L23: =IFERROR(__xludf.DUMMYFUNCTION("""COMPUTED_VALUE"""),"Facundo Laborde") -> Facundo Laborde | O23: =IFERROR(__xludf.DUMMYFUNCTION("""COMPUTED_VALUE""")," Facundo Laborde ") -> Facundo Laborde | P23: =IFERROR(__xludf.DUMMYFUNCTION("""COMPUTED_VALUE"""),"Expresion") -> Expresion | Q23: =IFERROR(__xludf.DUMMYFUNCTION("""COMPUTED_VALUE"""),"Mantiene") -> Mantiene
A24: =O24 -> Valeria Cerruti | B24: =IFERROR(__xludf.DUMMYFUNCTION("""COMPUTED_VALUE"""),12.0) -> 12 | C24: =IFERROR(__xludf.DUMMYFUNCTION("""COMPUTED_VALUE"""),"1º A") -> 1º A | F24: =IFERROR(__xludf.DUMMYFUNCTION("""COMPUTED_VALUE"""),"Nat Science") -> Nat Science | G24: =IFERROR(__xludf.DUMMYFUNCTION("""COMPUTED_VALUE"""),"si") -> si | I24: =IFERROR(__xludf.DUMMYFUNCTION("""COMPUTED_VALUE"""),4.0) -> 4 | K24: =IFERROR(__xludf.DUMMYFUNCTION("""COMPUTED_VALUE"""),"Natural Sciences") -> Natural Sciences | L24: =IFERROR(__xludf.DUMMYFUNCTION("""COMPUTED_VALUE"""),"Cecilia Garcia Reinoso") -> Cecilia Garcia Reinoso | O24: =IFERROR(__xludf.DUMMYFUNCTION("""COMPUTED_VALUE"""),"Valeria Cerruti") -> Valeria Cerruti | P24: =IFERROR(__xludf.DUMMYFUNCTION("""COMPUTED_VALUE"""),"Exactas") -> Exactas | Q24: =IFERROR(__xludf.DUMMYFUNCTION("""COMPUTED_VALUE"""),"Nuevo x baja de profesor") -> Nuevo x baja de profesor
A25: =O25 -> Cecilia Lund Petersen | B25: =IFERROR(__xludf.DUMMYFUNCTION("""COMPUTED_VALUE"""),12.0) -> 12 | C25: =IFERROR(__xludf.DUMMYFUNCTION("""COMPUTED_VALUE"""),"1º B") -> 1º B | G25: =IFERROR(__xludf.DUMMYFUNCTION("""COMPUTED_VALUE"""),"si") -> si | I25: =IFERROR(__xludf.DUMMYFUNCTION("""COMPUTED_VALUE"""),4.0) -> 4 | K25: =IFERROR(__xludf.DUMMYFUNCTION("""COMPUTED_VALUE"""),"Natural Sciences") -> Natural Sciences | L25: =IFERROR(__xludf.DUMMYFUNCTION("""COMPUTED_VALUE"""),"Cecilia Lund Petersen") -> Cecilia Lund Petersen | O25: =IFERROR(__xludf.DUMMYFUNCTION("""COMPUTED_VALUE""")," Cecilia Lund Petersen ") -> Cecilia Lund Petersen | P25: =IFERROR(__xludf.DUMMYFUNCTION("""COMPUTED_VALUE"""),"Exactas") -> Exactas | Q25: =IFERROR(__xludf.DUMMYFUNCTION("""COMPUTED_VALUE"""),"Mantiene") -> Mantiene
A26: =O26 -> Aylén Junquet | B26: =IFERROR(__xludf.DUMMYFUNCTION("""COMPUTED_VALUE"""),13.0) -> 13 | C26: =IFERROR(__xludf.DUMMYFUNCTION("""COMPUTED_VALUE"""),"1º A") -> 1º A | I26: =IFERROR(__xludf.DUMMYFUNCTION("""COMPUTED_VALUE"""),1.0) -> 1 | K26: =IFERROR(__xludf.DUMMYFUNCTION("""COMPUTED_VALUE"""),"Orientación") -> Orientación | L26: =IFERROR(__xludf.DUMMYFUNCTION("""COMPUTED_VALUE"""),"Pilar Azqueta") -> Pilar Azqueta | O26: =IFERROR(__xludf.DUMMYFUNCTION("""COMPUTED_VALUE""")," Aylén Junquet ") -> Aylén Junquet | P26: =IFERROR(__xludf.DUMMYFUNCTION("""COMPUTED_VALUE"""),"Orientacion") -> Orientacion | Q26: =IFERROR(__xludf.DUMMYFUNCTION("""COMPUTED_VALUE"""),"Nuevo x baja de profesor") -> Nuevo x baja de profesor
A27: =O27 -> Juan Ignacio Cacciamano | B27: =IFERROR(__xludf.DUMMYFUNCTION("""COMPUTED_VALUE"""),13.0) -> 13 | C27: =IFERROR(__xludf.DUMMYFUNCTION("""COMPUTED_VALUE"""),"1º B") -> 1º B | I27: =IFERROR(__xludf.DUMMYFUNCTION("""COMPUTED_VALUE"""),1.0) -> 1 | K27: =IFERROR(__xludf.DUMMYFUNCTION("""COMPUTED_VALUE"""),"Orientación") -> Orientación | L27: =IFERROR(__xludf.DUMMYFUNCTION("""COMPUTED_VALUE"""),"Nelson Aquino") -> Nelson Aquino | M27: =IFERROR(__xludf.DUMMYFUNCTION("""COMPUTED_VALUE"""),"Nicolás Leonel Mai") -> Nicolás Leonel Mai | O27: =IFERROR(__xludf.DUMMYFUNCTION("""COMPUTED_VALUE"""),"Juan Ignacio Cacciamano") -> Juan Ignacio Cacciamano | P27: =IFERROR(__xludf.DUMMYFUNCTION("""COMPUTED_VALUE"""),"Orientacion") -> Orientacion | Q27: =IFERROR(__xludf.DUMMYFUNCTION("""COMPUTED_VALUE"""),"Nuevo x baja de profesor") -> Nuevo x baja de profesor
A28: =O28 -> Bentes | B28: =IFERROR(__xludf.DUMMYFUNCTION("""COMPUTED_VALUE"""),14.0) -> 14 | C28: =IFERROR(__xludf.DUMMYFUNCTION("""COMPUTED_VALUE"""),"1º A") -> 1º A | I28: =IFERROR(__xludf.DUMMYFUNCTION("""COMPUTED_VALUE"""),2.0) -> 2 | K28: =IFERROR(__xludf.DUMMYFUNCTION("""COMPUTED_VALUE"""),"Portugués") -> Portugués | L28: =IFERROR(__xludf.DUMMYFUNCTION("""COMPUTED_VALUE"""),"Norma Beatriz Kimmel") -> Norma Beatriz Kimmel | O28: =IFERROR(__xludf.DUMMYFUNCTION("""COMPUTED_VALUE"""),"Bentes") -> Bentes | P28: =IFERROR(__xludf.DUMMYFUNCTION("""COMPUTED_VALUE"""),"Expresion") -> Expresion | Q28: =IFERROR(__xludf.DUMMYFUNCTION("""COMPUTED_VALUE"""),"Nuevo x baja de profesor") -> Nuevo x baja de profesor
A29: =O29 -> Bentes | B29: =IFERROR(__xludf.DUMMYFUNCTION("""COMPUTED_VALUE"""),14.0) -> 14 | C29: =IFERROR(__xludf.DUMMYFUNCTION("""COMPUTED_VALUE"""),"1º B") -> 1º B | I29: =IFERROR(__xludf.DUMMYFUNCTION("""COMPUTED_VALUE"""),2.0) -> 2 | K29: =IFERROR(__xludf.DUMMYFUNCTION("""COMPUTED_VALUE"""),"Portugués") -> Portugués | L29: =IFERROR(__xludf.DUMMYFUNCTION("""COMPUTED_VALUE"""),"Norma Beatriz Kimmel") -> Norma Beatriz Kimmel | O29: =IFERROR(__xludf.DUMMYFUNCTION("""COMPUTED_VALUE""")," Bentes ") -> Bentes | P29: =IFERROR(__xludf.DUMMYFUNCTION("""COMPUTED_VALUE"""),"Expresion") -> Expresion | Q29: =IFERROR(__xludf.DUMMYFUNCTION("""COMPUTED_VALUE"""),"Nuevo x baja de profesor") -> Nuevo x baja de profesor
A30: =O30 -> Roberta Ludueña | B30: =IFERROR(__xludf.DUMMYFUNCTION("""COMPUTED_VALUE"""),15.0) -> 15 | C30: =IFERROR(__xludf.DUMMYFUNCTION("""COMPUTED_VALUE"""),"1º A") -> 1º A | G30: =IFERROR(__xludf.DUMMYFUNCTION("""COMPUTED_VALUE"""),"si") -> si | I30: =IFERROR(__xludf.DUMMYFUNCTION("""COMPUTED_VALUE"""),4.0) -> 4 | K30: =IFERROR(__xludf.DUMMYFUNCTION("""COMPUTED_VALUE"""),"Prácticas del Lenguaje") -> Prácticas del Lenguaje | L30: =IFERROR(__xludf.DUMMYFUNCTION("""COMPUTED_VALUE"""),"Soledad Vilar") -> Soledad Vilar | O30: =IFERROR(__xludf.DUMMYFUNCTION("""COMPUTED_VALUE"""),"Roberta Ludueña") -> Roberta Ludueña | P30: =IFERROR(__xludf.DUMMYFUNCTION("""COMPUTED_VALUE"""),"Expresion") -> Expresion | Q30: =IFERROR(__xludf.DUMMYFUNCTION("""COMPUTED_VALUE"""),"Nuevo") -> Nuevo
A31: =O31 -> Mercedes Vitullo | B31: =IFERROR(__xludf.DUMMYFUNCTION("""COMPUTED_VALUE"""),15.0) -> 15 | C31: =IFERROR(__xludf.DUMMYFUNCTION("""COMPUTED_VALUE"""),"1º B") -> 1º B | G31: =IFERROR(__xludf.DUMMYFUNCTION("""COMPUTED_VALUE"""),"si") -> si | K31: =IFERROR(__xludf.DUMMYFUNCTION("""COMPUTED_VALUE"""),"Prácticas del Lenguaje") -> Prácticas del Lenguaje | L31: =IFERROR(__xludf.DUMMYFUNCTION("""COMPUTED_VALUE"""),"Soledad Vilar") -> Soledad Vilar | O31: =IFERROR(__xludf.DUMMYFUNCTION("""COMPUTED_VALUE""")," Mercedes Vitullo ") -> Mercedes Vitullo | P31: =IFERROR(__xludf.DUMMYFUNCTION("""COMPUTED_VALUE"""),"Expresion") -> Expresion | Q31: =IFERROR(__xludf.DUMMYFUNCTION("""COMPUTED_VALUE"""),"Nuevo") -> Nuevo
A32: =O32 | B32: =IFERROR(__xludf.DUMMYFUNCTION("""COMPUTED_VALUE"""),16.0) -> 16 | C32: =IFERROR(__xludf.DUMMYFUNCTION("""COMPUTED_VALUE"""),"1º A") -> 1º A
A33: =O33 | B33: =IFERROR(__xludf.DUMMYFUNCTION("""COMPUTED_VALUE"""),16.0) -> 16 | C33: =IFERROR(__xludf.DUMMYFUNCTION("""COMPUTED_VALUE"""),"1º B") -> 1º B
A34: =O34 | B34: =IFERROR(__xludf.DUMMYFUNCTION("""COMPUTED_VALUE"""),17.0) -> 17 | C34: =IFERROR(__xludf.DUMMYFUNCTION("""COMPUTED_VALUE"""),"1º A") -> 1º A
A35: =O35 | B35: =IFERROR(__xludf.DUMMYFUNCTION("""COMPUTED_VALUE"""),17.0) -> 17 | C35: =IFERROR(__xludf.DUMMYFUNCTION("""COMPUTED_VALUE"""),"1º B") -> 1º B
A36: =O36 | B36: =IFERROR(__xludf.DUMMYFUNCTION("""COMPUTED_VALUE"""),18.0) -> 18 | C36: =IFERROR(__xludf.DUMMYFUNCTION("""COMPUTED_VALUE"""),"1º A") -> 1º A
A37: =O37 | B37: =IFERROR(__xludf.DUMMYFUNCTION("""COMPUTED_VALUE"""),18.0) -> 18 | C37: =IFERROR(__xludf.DUMMYFUNCTION("""COMPUTED_VALUE"""),"1º B") -> 1º B
A38: =O38 | B38: =IFERROR(__xludf.DUMMYFUNCTION("""COMPUTED_VALUE"""),19.0) -> 19 | C38: =IFERROR(__xludf.DUMMYFUNCTION("""COMPUTED_VALUE"""),"1º A") -> 1º A
A39: =O39 | B39: =IFERROR(__xludf.DUMMYFUNCTION("""COMPUTED_VALUE"""),19.0) -> 19 | C39: =IFERROR(__xludf.DUMMYFUNCTION("""COMPUTED_VALUE"""),"1º B") -> 1º B
A40: =O40 | B40: =IFERROR(__xludf.DUMMYFUNCTION("""COMPUTED_VALUE"""),20.0) -> 20 | C40: =IFERROR(__xludf.DUMMYFUNCTION("""COMPUTED_VALUE"""),"1º A") -> 1º A
...

Sheet Reemplazos x profes
A1: Profesor que reemplaza en la clase
